2023-05-23 22:35:51,306 [MainThread  ] [INFO ]  Extracting from OMOP with arguments Namespace(simple_source='etl_input/simple_femr', target_location='/tmp/tmppc945j8a/extract', temp_location='/tmp/tmppc945j8a/logs', num_threads=2, athena_download=None)
2023-05-23 22:35:51,306 [MainThread  ] [INFO ]  Converting to events
2023-05-23 22:35:51,333 [MainThread  ] [CRITI]  [Errno 21] Is a directory: 'etl_input/simple_femr/.ipynb_checkpoints'
multiprocessing.pool.RemoteTraceback:
"""
Traceback (most recent call last):
  File "/home/ethanid/miniconda3/envs/piton_debug/lib/python3.10/multiprocessing/pool.py", line 125, in worker
    result = (True, func(*args, **kwds))
  File "/local-scratch/nigam/projects/ethanid/femr_develop/femr/src/femr/etl_pipelines/simple.py", line 29, in get_concept_ids_from_file
    f = stack.enter_context(open(filename, "r"))
IsADirectoryError: [Errno 21] Is a directory: 'etl_input/simple_femr/.ipynb_checkpoints'
"""

The above exception was the direct cause of the following exception:

Traceback (most recent call last):
  File "/local-scratch/nigam/projects/ethanid/femr_develop/femr/src/femr/etl_pipelines/simple.py", line 153, in etl_simple_femr_program
    for f_concepts in pool.imap_unordered(get_concept_ids_from_file, input_files):
  File "/home/ethanid/miniconda3/envs/piton_debug/lib/python3.10/multiprocessing/pool.py", line 873, in next
    raise value
IsADirectoryError: [Errno 21] Is a directory: 'etl_input/simple_femr/.ipynb_checkpoints'
2023-05-23 22:36:19,886 [MainThread  ] [INFO ]  Extracting from OMOP with arguments Namespace(simple_source='etl_input/simple_femr', target_location='/tmp/tmppc945j8a/extract', temp_location='/tmp/tmppc945j8a/logs', num_threads=2, athena_download=None)
2023-05-23 22:36:19,893 [MainThread  ] [INFO ]  Converting to events
2023-05-23 22:36:20,015 [MainThread  ] [INFO ]  Converting to patients
2023-05-23 22:36:20,058 [MainThread  ] [INFO ]  Converting to extract
